Workbook

Sheet Show Dates
A1: Title | B1: Type | C1: Category | D1: Event Date(s) | E1: actors/tech
A2: Finding Nemo | B2: Show | C2: Theater | D2: 07/24-25/2026 | E2: 5pm,8pm and 10am | F2: Cash box, square, ludus, table, Ticket box,
A4: Back to School Event | B4: Event | C4: General | D4: 46253 | F4: Welcome Flyers
A6: Ice Cream Social | B6: Show | C6: General | D6: 46254 | F6: Welcome Flyers Face Paint? Pay a Cone Forward?
A8: Heros vs Villans | B8: Show | C8: Theater | D8: 46289
A10: NCTS | B10: Event | C10: General | D10: 10/29-31/2026 | F10: *~$50Fees for Tshirts and Picnic type lunchbox, Festival Entrance,
A12: Fall Concert for Chorus | B12: Show | C12: Choir | F12: *Bake Sale with Coffee
A14: The Great Gatsby | B14: Show | C14: Theater | D14: 09/12/2026 Auditions | E14: 20/15-30 | F14: Dues $125 for non volunteers, $100 for actors, $75 for Tech
D15: 10/7-8/2026 Call backs
D16: 11/09-11/2026 Tech Week
D17: 11/12-14/2026 Show
A19: Southern Christmas Show* | B19: Show | C19: Choir | D19: 11/11-22/2026
A21: Biltmore performance* | B21: Show | C21: Choir | D21: 46357
A23: Revue in Reverse * | B23: Theater | C23: Theater | D23: 46036 | F23: *Dues for Tshirts, lite concessions
D24: or 01/7/2026 *Check date
A26: Alice by Heart | B26: Theater | C26: Theater | D26: 12/1-2/2026 Auditions | E26: 25/15-30 | F26: Dues $125 for non volunteers, $100 for actors, $75 for Tech
D27: 12/10-11/2026 Show
A29: Holiday Bazar | B29: Event | C29: General | D29: 12/5-6/2026
A31: Italian Dinner* | B31: Choir | C31: Choir | D31: 46082
A33: Dreams vs Nightmare | B33: Show | C33: Theater | D33: 46106 | F33: voting option this year
A35: Hunchback of Notre Dame | B35: Show | C35: Theater | D35: 10/1/2026 Informational meeting
D36: 10/9/2026 Auditions | E36: 30-35/15-30
D37: 04/4-7/2026 Tech Week
D38: 04/08-10 & 15-17/2026 Show
A40: Theatre I & II Production | B40: Show | C40: Theater | D40: 46153
A42: Senior Showcase | B42: Show | C42: Theater | D42: 46157
A44: Carowinds | B44: Shows | C44: Choir | D44: 46143
E46: *Recycle Programs? May need less

Sheet Sheet7
A2: Publix | B2: Box Sandwiches | C2: ~12.00/box
A3: Chic-fil-A | B3: Chicken Sandwich | C3: 125/25 Sandwiches
A4: Pizza Hut | B4: personal pan pizza | C4: 4.79/pizza
A5: Jersey Mikes | B5: Turkey Provolone | C5: 7.16/Sandwich | D5: 85.95/12

Sheet Great Gatsby
A1: Merchandise
A2: Custom Cards | B2: ~$2/pack (12)
A3: Paper Fans | B3: ~$1/fan (12)
A4: Art Deco Paintings | B4: ~$1.50/canvas | D4: Audition Dates
A5: Pearls | B5: ~$0.50/necklace | D5: Play dates
A6: Garters | B6: ~$1/garter (12) | D6: Tech Week
A9: Food
A10: Cracker Jacks | B10: ~0.30/bag
A11: Water | B11: ~0.20/bottle
A12: Coffee
A13: Green Lantern Drink | B13: ~0.25/ice cube
A14: Shirley Temples
A15: Salt Water Taffy
A16: Pizza | B16: ~$2/slice
A17: Soft Pretzels | B17: ~$1/Pretzel
A18: Popcorn
A19: fudge
A20: Candy Stix | B20: ~0.30/stick
A21: hoochi coochie cups
A22: carmel cremes
A24: Decor
A25: Black and Gold Tableclothes
A26: Vintage Candy Jars
A27: Gold Trays
A28: Deco Art Signs | B28: ~$1.52/poster (pk 6)

Sheet Ice Cream Social
A2: Have flyer ready to handout
A3: Ice Cream playlist Speakers? | D3: Aug 20th, Mineral Springs 12-4
A4: Bags game?
A5: Bocce?
A6: Sidewalk Chalk?
A7: Character Dress up?
A8: Face painting?
A9: Balloon animals?
A10: Bubble Machine?
A11: Get reminders out especially to elementary and middle school
A12: Posters to have outside ice cream shop?
A14: Megaphone=Ice Cream Jokes

Sheet Alice by Heart
A1: Merchandise
A2: Playing Cards
A3: Dog tags
A8: Food
A9: Butterfly tea lemonade
A10: Boba tea
A11: Finger Sandwiches
A12: Eat Me Cookies
A13: Drink Me Drink
A14: Red Candies
A15: Carrot Cake/Red Velvet Cupcakes/Bundt Cakes
A16: White Cheddar Popcorn
... A26: Black light/Laundry detergent

Sheet Hunchback
A1: Merchandise
A2: King of Fools Crown | B2: felt?
A3: Esmerelda's Potion
A4: stained glass window kits/or already made
A5: Tambourines | B5: ~$1.67/ per instrument
A6: Scarves
A7: mini gargoyoles to paint at home
A8: masquarade?
A13: Food
A14: Water
A15: Coffee

Sheet Misc
A2: Merchandise ideas
A3: Buttons
A4: Stickers
A5: Magnets
A6: Show Posters Signed by Cast
A7: Show Themed cups
A8: Light up items

Sheet Copy of Theater Budget
A1: 2025-26 CHAOS THEATER BUDGET PLAN
A2: Budget Code | B2: Category 1 | C2: Show Name | D2: Category 2 | E2: Projected Expense | F2: Expected Income | G2: Actual Expense | H2: Actual Income | I2: Comments
A3: T1000 | B3: Summer Camp 1 | C3: Finding Nemo | D3: Dues | F3: 2463.75 | G3: =SUM(SUMIFS(GL!$C:$C,GL!$G:$G,CONCATENATE(A3,"*"),GL!$F:$F,"Refund"),SUMIFS(GL!$C:$C,GL!$G:$G,CONCATENATE(A3,"*"),GL!$F:$F,"Expense")) -> #N/A | H3: =SUMIFS(GL!$C:$C,GL!$G:$G,CONCATENATE($A3,"*"),GL!$F:$F,"Income") -> #N/A
A4: T1001 | B4: Summer Camp 1 | C4: Finding Nemo | D4: T-shirts | E4: -344.94 | G4: =SUM(SUMIFS(GL!$C:$C,GL!$G:$G,CONCATENATE(A4,"*"),GL!$F:$F,"Refund"),SUMIFS(GL!$C:$C,GL!$G:$G,CONCATENATE(A4,"*"),GL!$F:$F,"Expense")) -> #N/A | H4: =SUMIFS(GL!$C:$C,GL!$G:$G,CONCATENATE($A4,"*"),GL!$F:$F,"Income") -> #N/A
A5: T1002 | B5: Summer Camp 2 | C5: Finding Nemo | D5: Dues | F5: 5580 | G5: =SUM(SUMIFS(GL!$C:$C,GL!$G:$G,CONCATENATE(A5,"*"),GL!$F:$F,"Refund"),SUMIFS(GL!$C:$C,GL!$G:$G,CONCATENATE(A5,"*"),GL!$F:$F,"Expense")) -> #N/A | H5: =SUMIFS(GL!$C:$C,GL!$G:$G,CONCATENATE($A5,"*"),GL!$F:$F,"Income") -> #N/A
A6: T1003 | B6: Summer Camp 2 | C6: Finding Nemo | D6: T-shirts | E6: -669.55 | G6: =SUM(SUMIFS(GL!$C:$C,GL!$G:$G,CONCATENATE(A6,"*"),GL!$F:$F,"Refund"),SUMIFS(GL!$C:$C,GL!$G:$G,CONCATENATE(A6,"*"),GL!$F:$F,"Expense")) -> #N/A | H6: =SUMIFS(GL!$C:$C,GL!$G:$G,CONCATENATE($A6,"*"),GL!$F:$F,"Income") -> #N/A
A7: T1004 | B7: Summer Camp 1 & 2 | C7: Finding Nemo | D7: Marketing | E7: -59.07 | G7: =SUM(SUMIFS(GL!$C:$C,GL!$G:$G,CONCATENATE(A7,"*"),GL!$F:$F,"Refund"),SUMIFS(GL!$C:$C,GL!$G:$G,CONCATENATE(A7,"*"),GL!$F:$F,"Expense")) -> #N/A | H7: =SUMIFS(GL!$C:$C,GL!$G:$G,CONCATENATE($A7,"*"),GL!$F:$F,"Income") -> #N/A
A8: T1005 | B8: Summer Camp 1 & 2 | C8: Finding Nemo | D8: Concessions / meals | E8: -102.35 | G8: =SUM(SUMIFS(GL!$C:$C,GL!$G:$G,CONCATENATE(A8,"*"),GL!$F:$F,"Refund"),SUMIFS(GL!$C:$C,GL!$G:$G,CONCATENATE(A8,"*"),GL!$F:$F,"Expense")) -> #N/A | H8: =SUMIFS(GL!$C:$C,GL!$G:$G,CONCATENATE($A8,"*"),GL!$F:$F,"Income") -> #N/A
A9: T1006 | B9: Summer Camp 1 & 2 | C9: Finding Nemo | D9: Ticket Sales | F9: 290 | G9: =SUM(SUMIFS(GL!$C:$C,GL!$G:$G,CONCATENATE(A9,"*"),GL!$F:$F,"Refund"),SUMIFS(GL!$C:$C,GL!$G:$G,CONCATENATE(A9,"*"),GL!$F:$F,"Expense")) -> #N/A | H9: =SUMIFS(GL!$C:$C,GL!$G:$G,CONCATENATE($A9,"*"),GL!$F:$F,"Income") -> #N/A | I9: Tickets for student performance X 10/ticket
A10: T1007 | B10: Summer Camp 1 & 2 | C10: Finding Nemo | D10: Licensing | E10: -1235 | G10: =SUM(SUMIFS(GL!$C:$C,GL!$G:$G,CONCATENATE(A10,"*"),GL!$F:$F,"Refund"),SUMIFS(GL!$C:$C,GL!$G:$G,CONCATENATE(A10,"*"),GL!$F:$F,"Expense")) -> #N/A | H10: =SUMIFS(GL!$C:$C,GL!$G:$G,CONCATENATE($A10,"*"),GL!$F:$F,"Income") -> #N/A
A11: T1008 | B11: Summer Camp 1 & 2 | C11: Finding Nemo | D11: Props, Set, Projections | E11: -354.04 | G11: =SUM(SUMIFS(GL!$C:$C,GL!$G:$G,CONCATENATE(A11,"*"),GL!$F:$F,"Refund"),SUMIFS(GL!$C:$C,GL!$G:$G,CONCATENATE(A11,"*"),GL!$F:$F,"Expense")) -> #N/A | H11: =SUMIFS(GL!$C:$C,GL!$G:$G,CONCATENATE($A11,"*"),GL!$F:$F,"Income") -> #N/A
B12: Totals | C12: =IFERROR(__xludf.DUMMYFUNCTION("AI(""Fill an appropriate value for this cell based on the table context"")"),"=AI(""Fill an appropriate value for this cell based on the table context"")") -> =AI("Fill an appropriate value for this cell based on the table context") | E12: =SUM(E3:E11) -> -2764.95 | F12: =SUM(F3:F11) -> 8333.75 | G12: =SUM(G3:G11) -> #N/A | H12: =SUM(H3:H11) -> #N/A
B13: Net | C13: =IFERROR(__xludf.DUMMYFUNCTION("AI(""Fill an appropriate value for this cell based on the table context"")"),"=AI(""Fill an appropriate value for this cell based on the table context"")") -> =AI("Fill an appropriate value for this cell based on the table context") | F13: =F12+E12 -> 5568.8 | H13: =H12+G12 -> #N/A | I13: Total Net to help cover Student NCTC Dues
C14: =IFERROR(__xludf.DUMMYFUNCTION("AI(""Fill an appropriate value for this cell based on the table context"")"),"=AI(""Fill an appropriate value for this cell based on the table context"")") -> =AI("Fill an appropriate value for this cell based on the table context")
A15: T1009 | B15: NCTC (20 kids) | C15: =IFERROR(__xludf.DUMMYFUNCTION("AI(""Fill an appropriate value for this cell based on the table context"")"),"=AI(""Fill an appropriate value for this cell based on the table context"")") -> =AI("Fill an appropriate value for this cell based on the table context") | D15: Dues | F15: 1000 | G15: =SUM(SUMIFS(GL!$C:$C,GL!$G:$G,CONCATENATE(A15,"*"),GL!$F:$F,"Refund"),SUMIFS(GL!$C:$C,GL!$G:$G,CONCATENATE(A15,"*"),GL!$F:$F,"Expense")) -> #N/A | H15: =SUMIFS(GL!$C:$C,GL!$G:$G,CONCATENATE($A15,"*"),GL!$F:$F,"Income") -> #N/A | I15: Dues: 20 X $50 includes Reg fee, Bus, Substitute, Tshirt, and some food
A16: T1010 | B16: NCTC (20 kids) | C16: =IFERROR(__xludf.DUMMYFUNCTION("AI(""Fill an appropriate value for this cell based on the table context"")"),"=AI(""Fill an appropriate value for this cell based on the table context"")") -> =AI("Fill an appropriate value for this cell based on the table context") | D16: Licensing: $1235 | E16: -150 | G16: =SUM(SUMIFS(GL!$C:$C,GL!$G:$G,CONCATENATE(A16,"*"),GL!$F:$F,"Refund"),SUMIFS(GL!$C:$C,GL!$G:$G,CONCATENATE(A16,"*"),GL!$F:$F,"Expense")) -> #N/A | H16: =SUMIFS(GL!$C:$C,GL!$G:$G,CONCATENATE($A16,"*"),GL!$F:$F,"Income") -> #N/A | I16: *need more more scripts!
A17: T1011 | B17: NCTC (20 kids) | C17: =IFERROR(__xludf.DUMMYFUNCTION("AI(""Fill an appropriate value for this cell based on the table context"")"),"=AI(""Fill an appropriate value for this cell based on the table context"")") -> =AI("Fill an appropriate value for this cell based on the table context") | D17: T-shirts | E17: -360 | F17: 70 | G17: =SUM(SUMIFS(GL!$C:$C,GL!$G:$G,CONCATENATE(A17,"*"),GL!$F:$F,"Refund"),SUMIFS(GL!$C:$C,GL!$G:$G,CONCATENATE(A17,"*"),GL!$F:$F,"Expense")) -> #N/A | H17: =SUMIFS(GL!$C:$C,GL!$G:$G,CONCATENATE($A17,"*"),GL!$F:$F,"Income") -> #N/A | I17: Tee Shirt Costs INCLUDED IN DUES: 20 X $12.00 per shirt
A18: T1012 | B18: NCTC (20 kids) | C18: =IFERROR(__xludf.DUMMYFUNCTION("AI(""Fill an appropriate value for this cell based on the table context"")"),"=AI(""Fill an appropriate value for this cell based on the table context"")") -> =AI("Fill an appropriate value for this cell based on the table context") | D18: Set Build | E18: -240 | G18: =SUM(SUMIFS(GL!$C:$C,GL!$G:$G,CONCATENATE(A18,"*"),GL!$F:$F,"Refund"),SUMIFS(GL!$C:$C,GL!$G:$G,CONCATENATE(A18,"*"),GL!$F:$F,"Expense")) -> #N/A | H18: =SUMIFS(GL!$C:$C,GL!$G:$G,CONCATENATE($A18,"*"),GL!$F:$F,"Income") -> #N/A
A19: T1013 | B19: NCTC (20 kids) | C19: =IFERROR(__xludf.DUMMYFUNCTION("AI(""Fill an appropriate value for this cell based on the table context"")"),"=AI(""Fill an appropriate value for this cell based on the table context"")") -> =AI("Fill an appropriate value for this cell based on the table context") | D19: Props | E19: -325 | G19: =SUM(SUMIFS(GL!$C:$C,GL!$G:$G,CONCATENATE(A19,"*"),GL!$F:$F,"Refund"),SUMIFS(GL!$C:$C,GL!$G:$G,CONCATENATE(A19,"*"),GL!$F:$F,"Expense")) -> #N/A | H19: =SUMIFS(GL!$C:$C,GL!$G:$G,CONCATENATE($A19,"*"),GL!$F:$F,"Income") -> #N/A
A20: T1014 | B20: NCTC (20 kids) | C20: =IFERROR(__xludf.DUMMYFUNCTION("AI(""Fill an appropriate value for this cell based on the table context"")"),"=AI(""Fill an appropriate value for this cell based on the table context"")") -> =AI("Fill an appropriate value for this cell based on the table context") | D20: Costumes | E20: -460 | G20: =SUM(SUMIFS(GL!$C:$C,GL!$G:$G,CONCATENATE(A20,"*"),GL!$F:$F,"Refund"),SUMIFS(GL!$C:$C,GL!$G:$G,CONCATENATE(A20,"*"),GL!$F:$F,"Expense")) -> #N/A | H20: =SUMIFS(GL!$C:$C,GL!$G:$G,CONCATENATE($A20,"*"),GL!$F:$F,"Income") -> #N/A
A21: T1015 | B21: NCTC (20 kids) | C21: =IFERROR(__xludf.DUMMYFUNCTION("AI(""Fill an appropriate value for this cell based on the table context"")"),"=AI(""Fill an appropriate value for this cell based on the table context"")") -> =AI("Fill an appropriate value for this cell based on the table context") | D21: Annual Membership Dues | E21: -400 | G21: =SUM(SUMIFS(GL!$C:$C,GL!$G:$G,CONCATENATE(A21,"*"),GL!$F:$F,"Refund"),SUMIFS(GL!$C:$C,GL!$G:$G,CONCATENATE(A21,"*"),GL!$F:$F,"Expense")) -> #N/A | H21: =SUMIFS(GL!$C:$C,GL!$G:$G,CONCATENATE($A21,"*"),GL!$F:$F,"Income") -> #N/A | I21: NCTC Member dues- $400/yr
A22: T1016 | B22: NCTC (20 kids) | C22: =IFERROR(__xludf.DUMMYFUNCTION("AI(""Fill an appropriate value for this cell based on the table context"")"),"=AI(""Fill an appropriate value for this cell based on the table context"")") -> =AI("Fill an appropriate value for this cell based on the table context") | D22: Festival Admission | E22: 0 | G22: =SUM(SUMIFS(GL!$C:$C,GL!$G:$G,CONCATENATE(A22,"*"),GL!$F:$F,"Refund"),SUMIFS(GL!$C:$C,GL!$G:$G,CONCATENATE(A22,"*"),GL!$F:$F,"Expense")) -> #N/A | H22: =SUMIFS(GL!$C:$C,GL!$G:$G,CONCATENATE($A22,"*"),GL!$F:$F,"Income") -> #N/A
A23: T1017 | B23: NCTC (20 kids) | C23: =IFERROR(__xludf.DUMMYFUNCTION("AI(""Fill an appropriate value for this cell based on the table context"")"),"=AI(""Fill an appropriate value for this cell based on the table context"")") -> =AI("Fill an appropriate value for this cell based on the table context") | D23: Transportation | E23: -250 | G23: =SUM(SUMIFS(GL!$C:$C,GL!$G:$G,CONCATENATE(A23,"*"),GL!$F:$F,"Refund"),SUMIFS(GL!$C:$C,GL!$G:$G,CONCATENATE(A23,"*"),GL!$F:$F,"Expense")) -> #N/A | H23: =SUMIFS(GL!$C:$C,GL!$G:$G,CONCATENATE($A23,"*"),GL!$F:$F,"Income") -> #N/A
A24: T1018 | B24: NCTC (20 kids) | C24: =IFERROR(__xludf.DUMMYFUNCTION("AI(""Fill an appropriate value for this cell based on the table context"")"),"=AI(""Fill an appropriate value for this cell based on the table context"")") -> =AI("Fill an appropriate value for this cell based on the table context") | D24: Meals & Snacks | E24: -1000 | G24: =SUM(SUMIFS(GL!$C:$C,GL!$G:$G,CONCATENATE(A24,"*"),GL!$F:$F,"Refund"),SUMIFS(GL!$C:$C,GL!$G:$G,CONCATENATE(A24,"*"),GL!$F:$F,"Expense")) -> #N/A | H24: =SUMIFS(GL!$C:$C,GL!$G:$G,CONCATENATE($A24,"*"),GL!$F:$F,"Income") -> #N/A | I24: 4 Meals
A25: T1019 | B25: NCTC (20 kids) | C25: =IFERROR(__xludf.DUMMYFUNCTION("AI(""Fill an appropriate value for this cell based on the table context"")"),"=AI(""Fill an appropriate value for this cell based on the table context"")") -> =AI("Fill an appropriate value for this cell based on the table context") | D25: Tickets | F25: 350 | G25: =SUM(SUMIFS(GL!$C:$C,GL!$G:$G,CONCATENATE(A25,"*"),GL!$F:$F,"Refund"),SUMIFS(GL!$C:$C,GL!$G:$G,CONCATENATE(A25,"*"),GL!$F:$F,"Expense")) -> #N/A | H25: =SUMIFS(GL!$C:$C,GL!$G:$G,CONCATENATE($A25,"*"),GL!$F:$F,"Income") -> #N/A | I25: Pay what you want donation based
A26: T1020 | B26: NCTC (20 kids) | C26: =IFERROR(__xludf.DUMMYFUNCTION("AI(""Fill an appropriate value for this cell based on the table context"")"),"=AI(""Fill an appropriate value for this cell based on the table context"")") -> =AI("Fill an appropriate value for this cell based on the table context") | D26: Playbills (Jan Show) | E26: -100 | G26: =SUM(SUMIFS(GL!$C:$C,GL!$G:$G,CONCATENATE(A26,"*"),GL!$F:$F,"Refund"),SUMIFS(GL!$C:$C,GL!$G:$G,CONCATENATE(A26,"*"),GL!$F:$F,"Expense")) -> #N/A | H26: =SUMIFS(GL!$C:$C,GL!$G:$G,CONCATENATE($A26,"*"),GL!$F:$F,"Income") -> #N/A
A27: T1021 | B27: NCTC (20 kids) | C27: =IFERROR(__xludf.DUMMYFUNCTION("AI(""Fill an appropriate value for this cell based on the table context"")"),"=AI(""Fill an appropriate value for this cell based on the table context"")") -> =AI("Fill an appropriate value for this cell based on the table context") | D27: Concessions (Jan Show) | E27: -100 | F27: 150 | G27: =SUM(SUMIFS(GL!$C:$C,GL!$G:$G,CONCATENATE(A27,"*"),GL!$F:$F,"Refund"),SUMIFS(GL!$C:$C,GL!$G:$G,CONCATENATE(A27,"*"),GL!$F:$F,"Expense")) -> #N/A | H27: =SUMIFS(GL!$C:$C,GL!$G:$G,CONCATENATE($A27,"*"),GL!$F:$F,"Income") -> #N/A
A28: T1022 | B28: NCTC (20 kids) | C28: =IFERROR(__xludf.DUMMYFUNCTION("AI(""Fill an appropriate value for this cell based on the table context"")"),"=AI(""Fill an appropriate value for this cell based on the table context"")") -> =AI("Fill an appropriate value for this cell based on the table context") | D28: Roses (Jan Show) | E28: -100 | F28: 200 | G28: =SUM(SUMIFS(GL!$C:$C,GL!$G:$G,CONCATENATE(A28,"*"),GL!$F:$F,"Refund"),SUMIFS(GL!$C:$C,GL!$G:$G,CONCATENATE(A28,"*"),GL!$F:$F,"Expense")) -> #N/A | H28: =SUMIFS(GL!$C:$C,GL!$G:$G,CONCATENATE($A28,"*"),GL!$F:$F,"Income") -> #N/A
B29: Totals | C29: =IFERROR(__xludf.DUMMYFUNCTION("AI(""Fill an appropriate value for this cell based on the table context"")"),"=AI(""Fill an appropriate value for this cell based on the table context"")") -> =AI("Fill an appropriate value for this cell based on the table context") | E29: =SUM(E15:E28) -> -3485 | F29: =SUM(F15:F28) -> 1770 | G29: =SUM(G15:G28) -> #N/A | H29: =SUM(H15:H28) -> #N/A
B30: Net | C30: =IFERROR(__xludf.DUMMYFUNCTION("AI(""Fill an appropriate value for this cell based on the table context"")"),"=AI(""Fill an appropriate value for this cell based on the table context"")") -> =AI("Fill an appropriate value for this cell based on the table context") | F30: =F29+E29 -> -1715 | H30: =H29+G29 -> #N/A
C31: =IFERROR(__xludf.DUMMYFUNCTION("AI(""Fill an appropriate value for this cell based on the table context"")"),"=AI(""Fill an appropriate value for this cell based on the table context"")") -> =AI("Fill an appropriate value for this cell based on the table context")
A32: T1023 | B32: Fall Revue #1 | C32: Villans | D32: Dues | F32: 1150 | G32: =SUM(SUMIFS(GL!$C:$C,GL!$G:$G,CONCATENATE(A32,"*"),GL!$F:$F,"Refund"),SUMIFS(GL!$C:$C,GL!$G:$G,CONCATENATE(A32,"*"),GL!$F:$F,"Expense")) -> #N/A | H32: =SUMIFS(GL!$C:$C,GL!$G:$G,CONCATENATE($A32,"*"),GL!$F:$F,"Income") -> #N/A | I32: Dues: 23 X $50 per student
A33: T1024 | B33: Fall Revue #1 | C33: Villans | D33: T-shirts | E33: -360 | G33: =SUM(SUMIFS(GL!$C:$C,GL!$G:$G,CONCATENATE(A33,"*"),GL!$F:$F,"Refund"),SUMIFS(GL!$C:$C,GL!$G:$G,CONCATENATE(A33,"*"),GL!$F:$F,"Expense")) -> #N/A | H33: =SUMIFS(GL!$C:$C,GL!$G:$G,CONCATENATE($A33,"*"),GL!$F:$F,"Income") -> #N/A | I33: INCLUDED IN DUES:23 X $12 per shirt
A34: T1025 | B34: Fall Revue #1 | C34: Villans | D34: Set/prop/costume | E34: 0 | G34: =SUM(SUMIFS(GL!$C:$C,GL!$G:$G,CONCATENATE(A34,"*"),GL!$F:$F,"Refund"),SUMIFS(GL!$C:$C,GL!$G:$G,CONCATENATE(A34,"*"),GL!$F:$F,"Expense")) -> #N/A | H34: =SUMIFS(GL!$C:$C,GL!$G:$G,CONCATENATE($A34,"*"),GL!$F:$F,"Income") -> #N/A
A35: T1026 | B35: Fall Revue #1 | C35: Villans | D35: Marketing | E35: -100 | G35: =SUM(SUMIFS(GL!$C:$C,GL!$G:$G,CONCATENATE(A35,"*"),GL!$F:$F,"Refund"),SUMIFS(GL!$C:$C,GL!$G:$G,CONCATENATE(A35,"*"),GL!$F:$F,"Expense")) -> #N/A | H35: =SUMIFS(GL!$C:$C,GL!$G:$G,CONCATENATE($A35,"*"),GL!$F:$F,"Income") -> #N/A
A36: T1027 | B36: Fall Revue #1 | C36: Villans | D36: Concessions | E36: -100 | F36: 150 | G36: =SUM(SUMIFS(GL!$C:$C,GL!$G:$G,CONCATENATE(A36,"*"),GL!$F:$F,"Refund"),SUMIFS(GL!$C:$C,GL!$G:$G,CONCATENATE(A36,"*"),GL!$F:$F,"Expense")) -> #N/A | H36: =SUMIFS(GL!$C:$C,GL!$G:$G,CONCATENATE($A36,"*"),GL!$F:$F,"Income") -> #N/A
A37: T1028 | B37: Fall Revue #1 | C37: Villans | D37: Flowers | E37: -100 | F37: 200 | G37: =SUM(SUMIFS(GL!$C:$C,GL!$G:$G,CONCATENATE(A37,"*"),GL!$F:$F,"Refund"),SUMIFS(GL!$C:$C,GL!$G:$G,CONCATENATE(A37,"*"),GL!$F:$F,"Expense")) -> #N/A | H37: =SUMIFS(GL!$C:$C,GL!$G:$G,CONCATENATE($A37,"*"),GL!$F:$F,"Income") -> #N/A
A38: T1029 | B38: Fall Revue #1 | C38: Villans | D38: Scholarship | E38: -50 | G38: =SUM(SUMIFS(GL!$C:$C,GL!$G:$G,CONCATENATE(A38,"*"),GL!$F:$F,"Refund"),SUMIFS(GL!$C:$C,GL!$G:$G,CONCATENATE(A38,"*"),GL!$F:$F,"Expense")) -> #N/A | H38: =SUMIFS(GL!$C:$C,GL!$G:$G,CONCATENATE($A38,"*"),GL!$F:$F,"Income") -> #N/A
A39: T1030 | B39: Fall Revue #1 | C39: Villans | D39: Meals | E39: 0 | F39: 0 | G39: =SUM(SUMIFS(GL!$C:$C,GL!$G:$G,CONCATENATE(A39,"*"),GL!$F:$F,"Refund"),SUMIFS(GL!$C:$C,GL!$G:$G,CONCATENATE(A39,"*"),GL!$F:$F,"Expense")) -> #N/A | H39: =SUMIFS(GL!$C:$C,GL!$G:$G,CONCATENATE($A39,"*"),GL!$F:$F,"Income") -> #N/A
A40: T1031 | B40: Fall Revue #1 | C40: Villans | D40: Ticket Sales | F40: 1000 | G40: =SUM(SUMIFS(GL!$C:$C,GL!$G:$G,CONCATENATE(A40,"*"),GL!$F:$F,"Refund"),SUMIFS(GL!$C:$C,GL!$G:$G,CONCATENATE(A40,"*"),GL!$F:$F,"Expense")) -> #N/A | H40: =SUMIFS(GL!$C:$C,GL!$G:$G,CONCATENATE($A40,"*"),GL!$F:$F,"Income") -> #N/A | I40: 100 tickets X $10/ticket
...
